<?xml version="1.0" ?>
<robot name="khi_ux150" xmlns:xacro="http://www.ros.org/wiki/xacro">

<xacro:macro name="khi_ux150" params="prefix">

<xacro:include filename="$(find khi_ux150_description)/urdf/materials.xacro" />
<xacro:include filename="$(find khi_ux150_description)/urdf/khi_ux150.trans" />
<xacro:include filename="$(find khi_ux150_description)/urdf/khi_ux150.gazebo" />

<link name="base_link">
    <visual>
        <geometry>
          <cylinder radius="0.38" length="0.275"/>
        </geometry>
        <origin xyz="0 0 0.1375" rpy = "0 0 0"/>
        <material name="khi_ux150_silver"/>
    </visual>
</link>

<link name="${prefix}moving_base">
  <inertial>
    <origin xyz="-0.028742946749996084 0.02089074368559713 0.19253316678423943" rpy="0 0 0"/>
    <mass value="1176.4967976314256"/>
    <inertia ixx="74.79433" iyy="78.77234" izz="96.294491" ixy="2.448201" iyz="1.501258" ixz="-4.602941"/>
  </inertial>
  <visual>
    <origin xyz="0 0 0" rpy="0 0 0"/>
    <geometry>
      <mesh filename="package://khi_ux150_description/meshes/moving_base.stl" scale="0.001 0.001 0.001"/>
    </geometry>
    <material name="khi_ux150_silver"/>
  </visual>
  <collision>
    <origin xyz="0 0 0" rpy="0 0 0"/>
    <geometry>
      <mesh filename="package://khi_ux150_description/meshes/moving_base.stl" scale="0.001 0.001 0.001"/>
    </geometry>
  </collision>
</link>

<link name="${prefix}parallel_1">
  <inertial>
    <origin xyz="0.03986921708247279 -0.11886034656515326 0.4283031108524009" rpy="0 0 0"/>
    <mass value="325.8856826388532"/>
    <inertia ixx="29.537916" iyy="28.866593" izz="2.891112" ixy="-0.023988" iyz="0.750748" ixz="-0.584538"/>
  </inertial>
  <visual>
    <origin xyz="0 0 0" rpy="0 0 0"/>
    <geometry>
      <mesh filename="package://khi_ux150_description/meshes/parallel_1.stl" scale="0.001 0.001 0.001"/>
    </geometry>
    <material name="khi_ux150_silver"/>
  </visual>
  <collision>
    <origin xyz="0 0 0" rpy="0 0 0"/>
    <geometry>
      <mesh filename="package://khi_ux150_description/meshes/parallel_1.stl" scale="0.001 0.001 0.001"/>
    </geometry>
  </collision>
</link>

<link name="${prefix}parallel_2">
  <inertial>
    <origin xyz="-0.0365150148298026 -0.0497024947083054 0.45207805995172545" rpy="0 0 0"/>
    <mass value="85.5516332403616"/>
    <inertia ixx="7.812717" iyy="7.793079" izz="0.245718" ixy="-0.000232" iyz="-0.009467" ixz="0.006094"/>
  </inertial>
  <visual>
    <origin xyz="0 0 0" rpy="0 0 0"/>
    <geometry>
      <mesh filename="package://khi_ux150_description/meshes/parallel_2.stl" scale="0.001 0.001 0.001"/>
    </geometry>
    <material name="khi_ux150_silver"/>
  </visual>
  <collision>
    <origin xyz="0 0 0" rpy="0 0 0"/>
    <geometry>
      <mesh filename="package://khi_ux150_description/meshes/parallel_2.stl" scale="0.001 0.001 0.001"/>
    </geometry>
  </collision>
</link>

<link name="${prefix}arm_support">
  <inertial>
    <origin xyz="0.05147265165690296 0.17435826511621838 0.20752905435106528" rpy="0 0 0"/>
    <mass value="382.54283393330616"/>
    <inertia ixx="10.909748" iyy="19.707084" izz="19.370158" ixy="1.971985" iyz="-1.309565" ixz="-3.359941"/>
  </inertial>
  <visual>
    <origin xyz="0 0 0" rpy="0 0 0"/>
    <geometry>
      <mesh filename="package://khi_ux150_description/meshes/arm_support.stl" scale="0.001 0.001 0.001"/>
    </geometry>
    <material name="khi_ux150_silver"/>
  </visual>
  <collision>
    <origin xyz="0 0 0" rpy="0 0 0"/>
    <geometry>
      <mesh filename="package://khi_ux150_description/meshes/arm_support.stl" scale="0.001 0.001 0.001"/>
    </geometry>
  </collision>
</link>

<link name="${prefix}arm">
  <inertial>
    <origin xyz="0.00022313109769489525 0.14237163988102403 0.3394239394935594" rpy="0 0 0"/>
    <mass value="283.2079465964804"/>
    <inertia ixx="54.253239" iyy="54.176125" izz="2.428567" ixy="-0.016596" iyz="1.878739" ixz="0.018447"/>
  </inertial>
  <visual>
    <origin xyz="0 0 0" rpy="0 0 0"/>
    <geometry>
      <mesh filename="package://khi_ux150_description/meshes/arm.stl" scale="0.001 0.001 0.001"/>
    </geometry>
    <material name="khi_ux150_silver"/>
  </visual>
  <collision>
    <origin xyz="0 0 0" rpy="0 0 0"/>
    <geometry>
      <mesh filename="package://khi_ux150_description/meshes/arm.stl" scale="0.001 0.001 0.001"/>
    </geometry>
  </collision>
</link>

<link name="${prefix}neck">
  <inertial>
    <origin xyz="8.17668405206362e-09 -0.0053868664486536955 0.1216289930409955" rpy="0 0 0"/>
    <mass value="11.12471949612164"/>
    <inertia ixx="0.050234" iyy="0.045915" izz="0.014664" ixy="0.0" iyz="0.002899" ixz="0.0"/>
  </inertial>
  <visual>
    <origin xyz="0 0 0" rpy="0 0 0"/>
    <geometry>
      <mesh filename="package://khi_ux150_description/meshes/neck.stl" scale="0.001 0.001 0.001"/>
    </geometry>
    <material name="khi_ux150_silver"/>
  </visual>
  <collision>
    <origin xyz="0 0 0" rpy="0 0 0"/>
    <geometry>
      <mesh filename="package://khi_ux150_description/meshes/neck.stl" scale="0.001 0.001 0.001"/>
    </geometry>
  </collision>
</link>

<link name="${prefix}head">
  <inertial>
    <origin xyz="0.0 0.044184610514243786 0.06257690433843299" rpy="0 0 0"/>
    <mass value="45.41875384971286"/>
    <inertia ixx="0.523197" iyy="0.363955" izz="0.34711" ixy="-0.0" iyz="-0.07141" ixz="-0.0"/>
  </inertial>
  <visual>
    <origin xyz="0 0 0" rpy="0 0 0"/>
    <geometry>
      <mesh filename="package://khi_ux150_description/meshes/head.stl" scale="0.001 0.001 0.001"/>
    </geometry>
    <material name="khi_ux150_silver"/>
  </visual>
  <collision>
    <origin xyz="0 0 0" rpy="0 0 0"/>
    <geometry>
      <mesh filename="package://khi_ux150_description/meshes/head.stl" scale="0.001 0.001 0.001"/>
    </geometry>
  </collision>
</link>

<link name="${prefix}plate">
  <inertial>
    <origin xyz="5.551115123125783e-17 0.0 0.010000000000000231" rpy="0 0 0"/>
    <mass value="3.9951633775701394"/>
    <inertia ixx="0.008223" iyy="0.008223" izz="0.01618" ixy="0.0" iyz="-0.0" ixz="0.0"/>
  </inertial>
  <visual>
    <origin xyz="0 0 0" rpy="0 0 0"/>
    <geometry>
      <mesh filename="package://khi_ux150_description/meshes/plate.stl" scale="0.001 0.001 0.001"/>
    </geometry>
    <material name="khi_ux150_silver"/>
  </visual>
  <collision>
    <origin xyz="0 0 0" rpy="0 0 0"/>
    <geometry>
      <mesh filename="package://khi_ux150_description/meshes/plate.stl" scale="0.001 0.001 0.001"/>
    </geometry>
  </collision>
</link>

<joint name="${prefix}jt1" type="revolute">
    <origin xyz="0.0 0.0 0.275" rpy="0 0 0"/>
    <parent link="base_link"/>
    <child link="${prefix}moving_base"/>
    <axis xyz="0.0 0.0 1.0"/>
    <limit lower="-3.1459" upper="3.1459" effort="1000" velocity="1"/>
</joint>

<joint name="${prefix}jt2" type="revolute">
    <origin xyz="0.135 -0.14 0.425" rpy="0 0 0"/>
    <parent link="${prefix}moving_base"/>
    <child link="${prefix}parallel_1"/>
    <axis xyz="0.0 -1.0 0.0"/>
    <limit lower="-1.13446" upper="1.22173" effort="1000" velocity="1"/>
</joint>

<joint name="${prefix}jt2_1" type="revolute">
    <origin xyz="-0.215 -0.2 0.46" rpy="0 0 0"/>
    <parent link="${prefix}moving_base"/>
    <child link="${prefix}parallel_2"/>
    <axis xyz="0.0 -1.0 0.0"/>
    <limit lower="-1.22173" upper="1.13446" effort="1000" velocity="1"/>
    <mimic joint="jt2" multiplier="1.0"/>
</joint>

<joint name="${prefix}jt2_2" type="revolute">
    <origin xyz="0.0 -0.26 0.9" rpy="0 0 0"/>
    <parent link="${prefix}parallel_1"/>
    <child link="${prefix}arm_support"/>
    <axis xyz="0.0 1.0 0.0"/>
    <limit lower="-1.22173" upper="1.13446" effort="1000" velocity="1"/>
    <mimic joint="jt2" multiplier="1.0"/>
</joint>

  <joint name="${prefix}jt3" type="revolute">
      <origin xyz="0.2 0.275 0.27" rpy="0 1.5707963 0"/>
      <parent link="${prefix}arm_support"/>
      <child link="${prefix}arm"/>
      <axis xyz="0.0 1.0 0.0"/>
      <limit lower="-1.578" upper="2.07694" effort="1000" velocity="1"/>
  </joint>

  <joint name="${prefix}jt4" type="revolute">
      <origin xyz="0.0 0.125 1.18" rpy="0 0 0"/>
      <parent link="${prefix}arm"/>
      <child link="${prefix}neck"/>
      <axis xyz="0.0 0.0 1.0"/>
      <limit lower="-4.88692" upper="4.88692" effort="1000" velocity="1"/>
  </joint>

  <joint name="${prefix}jt5" type="revolute">
      <origin xyz="0.0 -0.07 0.17" rpy="0 0 0"/>
      <parent link="${prefix}neck"/>
      <child link="${prefix}head"/>
      <axis xyz="0.0 -1.0 0.0"/>
      <limit lower="-2.18166" upper="2.18166" effort="1000" velocity="1"/>
  </joint>

  <joint name="${prefix}jt6" type="revolute">
      <origin xyz="0.0 0.07 0.185" rpy="0 0 0"/>
      <parent link="${prefix}head"/>
      <child link="${prefix}plate"/>
      <axis xyz="0.0 0.0 1.0"/>
      <limit lower="-6.28319" upper="6.28319" effort="1000" velocity="1"/>
  </joint>


</xacro:macro>
</robot>
